Workbook
Name Excel_BuiltIn__FilterDatabase: box2metadata!$A$1:$P$104

Sheet tab
A1: ENTITY | B1: SHORTNAME | C1: LABEL | D1: PRIORITY | E1: LEADING | F1: SECURITY
A2: Person | B2: details | C2: Profile | D2: 0 | E2: y | F2: PUBLIC
A3: Person | B3: publications | C3: Publications | D3: 4 | E3: n | F3: PUBLIC
A4: Person | B4: projects | C4: Projects | D4: 6 | E4: n | F4: PUBLIC
A5: Person | B5: collaboration | C5: Collaborations | D5: 8 | E5: n | F5: PUBLIC
A6: Person | B6: otherinfo | C6: Other | D6: 2 | E6: n | F6: PUBLIC
A7: Person | B7: indicators | C7: Metrics | D7: 6 | E7: n | F7: PUBLIC
A8: Person | B8: secure | C8: Secured Tab | D8: 6 | E8: n | F8: CUSTOM DATA
A9: OrgUnit | B9: maininformation | C9: Information | D9: 0 | E9: y | F9: PUBLIC
A10: OrgUnit | B10: organizations | C10: Organizations | D10: 16 | E10: n | F10: PUBLIC
A11: OrgUnit | B11: rppublications | C11: Researchers publications | D11: 4 | E11: n | F11: PUBLIC
A12: OrgUnit | B12: projects | C12: Projects | D12: 10 | E12: n | F12: PUBLIC
A13: OrgUnit | B13: rpprojects | C13: Researchers projects | D13: 8 | E13: n | F13: PUBLIC
A14: OrgUnit | B14: people | C14: People | D14: 2 | E14: n | F14: PUBLIC
A15: OrgUnit | B15: thesis | C15: Thesis | D15: 12 | E15: n | F15: PUBLIC
A16: OrgUnit | B16: collaboration | C16: Collaborations | D16: 14 | E16: n | F16: PUBLIC
A17: Project | B17: details | C17: Details | D17: 0 | E17: n | F17: PUBLIC
A18: Project | B18: outputs::projectoutputs | C18: Outputs::Publications | D18: 0 | E18: n | F18: PUBLIC
A19: Project | B19: outputs::fundings | C19: Outputs::Fundings | D19: 10 | E19: n | F19: PUBLIC
A20: Journal | B20: details | C20: Details | D20: 0 | E20: n | F20: PUBLIC
A21: Event | B21: details | C21: Details | D21: 0 | E21: n | F21: PUBLIC
A22: Equipment | B22: details | C22: Details | D22: 0 | E22: n | F22: PUBLIC
A23: Funding | B23: details | C23: Details | D23: 0 | E23: y | F23: PUBLIC
A24: Publication | B24: details | C24: Details | D24: 0 | E24: y | F24: PUBLIC
A25: Product | B25: details | C25: Details | D25: 0 | E25: n | F25: PUBLIC
A26: Patent | B26: details | C26: Details | D26: 0 | E26: n | F26: PUBLIC
A27: Thesis | B27: details | C27: Details | D27: 0 | E27: n | F27: PUBLIC

Sheet tab2box
A1: ENTITY | B1: TAB | C1: ROW | D1: ROW_STYLE | E1: CELL_STYLE | F1: BOXES
A2: OrgUnit | B2: maininformation | C2: 1 | F2: heading
A3: OrgUnit | B3: maininformation | C3: 2 | F3: details
A4: OrgUnit | B4: rppublications | C4: 1 | F4: rppublications
A5: OrgUnit | B5: projects | C5: 1 | F5: projects
A6: OrgUnit | B6: rpprojects | C6: 1 | F6: rpprojects
A7: OrgUnit | B7: people | C7: 1 | F7: people
A8: OrgUnit | B8: thesis | C8: 1 | F8: thesis
A9: OrgUnit | B9: collaboration | C9: 2 | F9: colaborations
A10: Project | B10: details | C10: 1 | D10: mb-3 | F10: primarydata
A11: Project | B11: details | C11: 2 | D11: mb-3 | F11: funding
A12: Project | B12: details | C12: 3 | D12: mb-3 | F12: researchers
A13: Project | B13: details | C13: 4 | D13: mb-3 | F13: organizations
A14: Project | B14: details | C14: 5 | D14: mb-3 | F14: categorization
A15: Project | B15: outputs::projectoutputs | C15: 1 | F15: researchoutputs
A16: Project | B16: outputs::fundings | C16: 1 | F16: fundings
A17: Funding | B17: details | C17: 1 | F17: heading
A18: Funding | B18: details | C18: 2 | F18: primarydata
A19: Funding | B19: details | C19: 3 | F19: financialdata
A20: Funding | B20: details | C20: 4 | E20: my-4 | F20: metrics
A21: Person | B21: details | C21: 1 | F21: heading
A22: Person | B22: details | C22: 2 | F22: namecard
A23: Person | B23: publications | C23: 2 | F23: researchoutputs
A24: Person | B24: projects | C24: 2 | F24: projects
A25: Person | B25: indicators | C25: 1 | F25: metrics
A26: Person | B26: indicators | C26: 2 | F26: usagemetrics
A27: Person | B27: otherinfo | C27: 1 | D27: mb-3 | F27: researcherprofile
A28: Person | B28: otherinfo | C28: 2 | D28: mb-3 | F28: media
A29: Person | B29: otherinfo | C29: 3 | D29: mb-3 | F29: qualifications
A30: Person | B30: otherinfo | C30: 4 | D30: mb-3 | F30: secure
A31: Person | B31: collaboration | C31: 2 | F31: colaborations
A32: Person | B32: secure | C32: 2 | F32: secure
A33: Journal | B33: details | C33: 1 | F33: details
A34: Journal | B34: details | C34: 2 | F34: metrics
A35: Event | B35: details | C35: 1 | F35: details
A36: Event | B36: details | C36: 2 | F36: metrics
A37: Equipment | B37: details | C37: 1 | F37: details
A38: Equipment | B38: details | C38: 2 | F38: metrics
A39: Publication | B39: details | C39: 1 | D39: mb-3 | F39: heading
A40: Publication | B40: details | C40: 5 | D40: mb-3 | F40: details
...

Sheet box
A1: ENTITY | B1: COLLAPSED | C1: TYPE | D1: SHORTNAME | E1: LABEL | F1: CONTAINER | G1: MINOR | H1: SECURITY | I1: STYLE
A2: Person | B2: n | D2: heading | F2: n | G2: n | H2: PUBLIC
A3: Person | B3: n | C3: RELATION | D3: projects | E3: Projects | F3: n | G3: n | H3: PUBLIC
A4: Person | B4: n | C4: RELATION | D4: researchoutputs | E4: Publications | F4: n | G4: n | H4: PUBLIC
A5: Person | B5: n | D5: qualifications | E5: Professional Qualifications | F5: n | G5: n | H5: PUBLIC
A6: Person | B6: n | D6: media | E6: Media Contact Directory | F6: n | G6: n | H6: PUBLIC
A7: Person | B7: n | D7: namecard | E7: Name Card | F7: n | G7: y | H7: PUBLIC
A8: Person | B8: n | D8: researcherprofile | E8: Profile | F8: n | G8: n | H8: PUBLIC
A9: Person | B9: n | C9: METRICS | D9: metrics | E9: Metrics | F9: n | G9: n | H9: PUBLIC
A10: Person | B10: n | C10: METRICS | D10: usagemetrics | E10: Usage Metrics | F10: n | G10: n | H10: PUBLIC
A11: Person | B11: n | D11: secure | E11: Secured box | F11: n | G11: y | H11: CUSTOM DATA
A12: Person | B12: n | C12: COLLABORATION | D12: colaborations | E12: Collabs | F12: n | G12: n | H12: PUBLIC
A13: OrgUnit | B13: n | C13: RELATION | D13: rpprojects | E13: OrgUnit's Researchers projects | F13: n | G13: n | H13: PUBLIC
A14: OrgUnit | B14: n | C14: RELATION | D14: rppublications | E14: OrgUnit's Researchers publications | F14: n | G14: n | H14: PUBLIC
A15: OrgUnit | B15: n | C15: RELATION | D15: people | E15: OrgUnit's Researchers | F15: n | G15: n | H15: PUBLIC
A16: OrgUnit | B16: n | C16: RELATION | D16: projects | E16: OrgUnit funded Projects | F16: n | G16: n | H16: PUBLIC
A17: OrgUnit | B17: n | C17: RELATION | D17: thesis | E17: OrgUnit Student thesis | F17: n | G17: n | H17: PUBLIC
A18: OrgUnit | B18: n | D18: heading | F18: n | G18: n | H18: PUBLIC
A19: OrgUnit | B19: n | D19: description | E19: Description | F19: n | G19: n | H19: PUBLIC
A20: OrgUnit | B20: n | C20: RELATION | D20: organizations | E20: SubOrgUnits | F20: n | G20: n | H20: PUBLIC
A21: OrgUnit | B21: n | D21: details | E21: Details | F21: n | G21: n | H21: PUBLIC
A22: OrgUnit | B22: n | D22: orgcard | E22: Card | F22: y | G22: y | H22: PUBLIC
A23: OrgUnit | B23: n | C23: METRICS | D23: metrics | E23: Metrics | F23: y | G23: n | H23: PUBLIC
A24: OrgUnit | B24: n | C24: COLLABORATION | D24: colaborations | E24: Collabs | F24: n | G24: n | H24: PUBLIC
A25: Project | B25: n | C25: RELATION | D25: researchoutputs | E25: Publications | F25: y | G25: n | H25: PUBLIC
A26: Project | B26: n | C26: RELATION | D26: fundings | E26: Fundings | F26: y | G26: n | H26: PUBLIC
A27: Project | B27: n | D27: primarydata | E27: Primary Data | F27: n | G27: n | H27: PUBLIC
A28: Project | B28: n | D28: funding | E28: Funding | F28: y | G28: n | H28: PUBLIC
A29: Project | B29: n | D29: researchers | E29: Researchers | F29: y | G29: n | H29: PUBLIC
A30: Project | B30: n | D30: organizations | E30: Organizations | F30: y | G30: n | H30: PUBLIC
A31: Project | B31: n | D31: categorization | E31: Categorization | F31: y | G31: n | H31: PUBLIC
A32: Project | B32: n | D32: projectcard | E32: Project Card | F32: y | G32: n | H32: PUBLIC
A33: Project | B33: n | C33: METRICS | D33: metrics | E33: Metrics | F33: y | G33: n | H33: PUBLIC
A34: Funding | B34: n | D34: heading | F34: n | G34: n | H34: PUBLIC
A35: Funding | B35: n | D35: primarydata | E35: Primary Data | F35: y | G35: n | H35: PUBLIC
A36: Funding | B36: n | D36: financialdata | E36: Financial Data | F36: y | G36: n | H36: CUSTOM DATA
A37: Funding | B37: n | C37: METRICS | D37: metrics | E37: Metrics | F37: y | G37: n | H37: PUBLIC
A38: Journal | B38: n | D38: details | E38: Journal description | F38: y | G38: n | H38: PUBLIC
A39: Journal | B39: n | C39: METRICS | D39: metrics | E39: Metrics | F39: y | G39: n | H39: PUBLIC
A40: Event | B40: n | D40: details | E40: Description | F40: y | G40: n | H40: PUBLIC
...

Sheet box2metadata
A1: ENTITY | B1: BOX | C1: ROW | D1: CELL | E1: FIELDTYPE | F1: METADATA | G1: VALUE | H1: BUNDLE | I1: LABEL | J1: LABEL_AS_HEADING | K1: RENDERING | L1: VALUES_INLINE | M1: ROW_STYLE | N1: CELL_STYLE | O1: STYLE_LABEL | P1: STYLE_VALUE
A2: OrgUnit | B2: description | C2: 1 | D2: 1 | E2: METADATA | F2: organization.address.addressCountry | I2: Country | J2: n | L2: n | O2: font-weight-bold col-3
A3: OrgUnit | B3: description | C3: 2 | D3: 1 | E3: METADATA | F3: organization.address.addressLocality | I3: City | J3: n | L3: n | O3: font-weight-bold col-3
A4: OrgUnit | B4: description | C4: 3 | D4: 1 | E4: METADATA | F4: dc.description.abstract | I4: Description | J4: n | K4: longtext | L4: n | O4: font-weight-bold col-3
A5: OrgUnit | B5: heading | C5: 1 | D5: 1 | E5: METADATA | F5: dc.title | J5: n | K5: heading | L5: n | N5: px-2 | O5: font-weight-bold col-3
A6: OrgUnit | B6: details | C6: 1 | D6: 2 | E6: METADATA | F6: oairecerif.acronym | I6: Acronym | J6: y | L6: n | N6: mb-2 col-12 col-md | O6: font-weight-bold col-12
A7: OrgUnit | B7: details | C7: 1 | D7: 2 | E7: METADATA | F7: organization.address.addressCountry | I7: Country | J7: y | L7: n | N7: mb-2 col-12 col-md | O7: font-weight-bold col-12
A8: OrgUnit | B8: details | C8: 1 | D8: 2 | E8: METADATA | F8: organization.address.addressLocality | I8: Locality | J8: y | L8: n | N8: mb-2 col-12 col-md | O8: font-weight-bold col-12
A9: OrgUnit | B9: details | C9: 1 | D9: 2 | E9: METADATA | F9: oairecerif.identifier.url | I9: Web | J9: y | K9: link | L9: n | N9: mb-2 col-12 col-md | O9: font-weight-bold col-12
A10: OrgUnit | B10: details | C10: 1 | D10: 2 | E10: METADATA | F10: antarc.institution.urlcris | I10: CRIS Web | J10: y | K10: link | L10: n | N10: mb-2 col-12 col-md | O10: font-weight-bold col-12
A11: OrgUnit | B11: details | C11: 1 | D11: 3 | E11: METADATA | F11: organization.foundingDate | I11: Founding Date | J11: y | K11: date | L11: n | N11: mb-2 col-12 col-md | O11: font-weight-bold col-12
A12: OrgUnit | B12: details | C12: 1 | D12: 3 | E12: METADATA | F12: organization.identifier.ror | I12: ROR Identifier | J12: y | K12: identifier.ror | L12: n | N12: mb-2 col-12 col-md | O12: font-weight-bold col-12
A13: OrgUnit | B13: details | C13: 1 | D13: 3 | E13: METADATA | F13: organization.identifier.isni | I13: ISNI Identifier | J13: y | L13: n | N13: mb-2 col-12 col-md | O13: font-weight-bold col-12
A14: OrgUnit | B14: details | C14: 1 | D14: 3 | E14: METADATA | F14: organization.identifier.rin | I14: RingGold Identifier | J14: y | L14: n | N14: mb-2 col-12 col-md | O14: font-weight-bold col-12
A15: OrgUnit | B15: details | C15: 1 | D15: 3 | E15: METADATA | F15: organization.identifier.crossrefid | I15: Crossref Identifier | J15: y | L15: n | N15: mb-2 col-12 col-md | O15: font-weight-bold col-12
A16: OrgUnit | B16: orgcard | C16: 1 | D16: 1 | E16: BITSTREAM | F16: dc.type | G16: logo | H16: ORIGINAL | J16: n | K16: thumbnail | L16: n | N16: col-3
A17: OrgUnit | B17: orgcard | C17: 1 | D17: 2 | E17: METADATA | F17: dc.title | I17: Organisation Name | J17: n | L17: n | N17: px-2 | O17: font-weight-bold col-3
A18: OrgUnit | B18: orgcard | C18: 1 | D18: 2 | E18: METADATA | F18: crisou.director | I18: Director | J18: n | K18: crisref | L18: n | O18: font-weight-bold col-3
A19: OrgUnit | B19: orgcard | C19: 1 | D19: 2 | E19: METADATA | F19: organization.parentOrganization | I19: Parent Organisation | J19: n | K19: crisref | L19: n | O19: font-weight-bold col-3
A20: OrgUnit | B20: orgcard | C20: 1 | D20: 2 | E20: METADATA | F20: organization.foundingDate | I20: Founding Date | J20: n | K20: date | L20: n | O20: font-weight-bold col-3
A21: OrgUnit | B21: orgcard | C21: 1 | D21: 2 | E21: METADATA | F21: organization.address.addressLocality | I21: City | J21: n | L21: n | O21: font-weight-bold col-3
A22: OrgUnit | B22: orgcard | C22: 1 | D22: 2 | E22: METADATA | F22: organization.address.addressCountry | I22: Country | J22: n | L22: n | O22: font-weight-bold col-3
A23: Project | B23: primarydata | C23: 1 | D23: 1 | E23: METADATA | F23: dc.title | J23: n | K23: heading | L23: n | N23: px-3 | O23: font-weight-bold col-3
A24: Project | B24: primarydata | C24: 2 | D24: 1 | E24: METADATA | F24: oairecerif.acronym | I24: INACH Code | J24: y | L24: y | N24: mb-2 col-12 col-md | O24: font-weight-bold col-12
A25: Project | B25: primarydata | C25: 3 | D25: 1 | E25: METADATA | F25: crispj.investigator | I25: Principal Research | J25: y | K25: crisref | L25: y | N25: mb-2 col-12 col-md | O25: font-weight-bold col-12
A26: Project | B26: primarydata | C26: 3 | D26: 2 | E26: METADATA | F26: crispj.coordinator | I26: Principal Institution | J26: y | K26: crisref | L26: y | N26: mb-2 col-12 col-md | O26: font-weight-bold col-12
A27: Project | B27: funding | C27: 1 | D27: 1 | E27: METADATA | F27: oairecerif.funder | I27: Funder Institution | J27: y | K27: crisref | L27: n | N27: mb-2 col-12 col-md | O27: font-weight-bold col-12
A28: Project | B28: funding | C28: 1 | D28: 2 | E28: METADATA | F28: antarc.funder.ror | I28: Funder ROR | J28: y | L28: n | N28: mb-2 col-12 col-md | O28: font-weight-bold col-12
A29: Project | B29: funding | C29: 1 | D29: 3 | E29: METADATA | F29: antarc.project.anid | I29: ANID Code | J29: y | L29: n | N29: mb-2 col-12 col-md | O29: font-weight-bold col-12
A30: Project | B30: funding | C30: 2 | D30: 1 | E30: METADATA | F30: oairecerif.project.startDate | I30: Start Date | J30: y | K30: date | L30: n | N30: mb-2 col-12 col-md | O30: font-weight-bold col-12
A31: Project | B31: funding | C31: 2 | D31: 2 | E31: METADATA | F31: oairecerif.project.endDate | I31: End Date | J31: y | K31: date | L31: n | N31: mb-2 col-12 col-md | O31: font-weight-bold col-12
A32: Project | B32: funding | C32: 2 | D32: 3 | E32: METADATA | F32: oairecerif.amount | I32: Amount (CLP) | J32: y | L32: n | N32: mb-2 col-12 col-md | O32: font-weight-bold col-12
A33: Project | B33: researchers | C33: 1 | D33: 1 | E33: METADATA | F33: crispj.coinvestigators | J33: n | K33: crisref | L33: n | N33: mb-2 col-12 col-md | O33: font-weight-bold col-12
A34: Project | B34: organizations | C34: 1 | D34: 1 | E34: METADATA | F34: crispj.organization | J34: n | K34: crisref | L34: n | N34: mb-2 col-12 col-md | O34: font-weight-bold col-12
A35: Project | B35: categorization | C35: 1 | D35: 1 | E35: METADATA | F35: antarc.area.ods | I35: Research ODS | J35: y | L35: n | N35: mb-2 | O35: font-weight-bold col-12
A36: Project | B36: categorization | C36: 1 | D36: 2 | E36: METADATA | F36: antarc.area.anid | I36: Research ANID | J36: y | L36: n | N36: mb-2 | O36: font-weight-bold col-12
A37: Project | B37: categorization | C37: 1 | D37: 3 | E37: METADATA | F37: antarc.area.inach | I37: Research INACH | J37: y | L37: n | N37: mb-2 | O37: font-weight-bold col-12
A38: Project | B38: projectcard | C38: 1 | D38: 1 | E38: BITSTREAM | F38: dc.type | G38: logo | H38: ORIGINAL | J38: n | K38: thumbnail | L38: n | N38: col-3
A39: Project | B39: projectcard | C39: 1 | D39: 2 | E39: METADATA | F39: dc.title | I39: Project Title | J39: n | L39: n | N39: px-2 | O39: font-weight-bold col-3
A40: Project | B40: projectcard | C40: 1 | D40: 2 | E40: METADATA | F40: oairecerif.internalid | I40: Internal ID | J40: n | L40: n | O40: font-weight-bold col-3
...

Sheet metadatagroups
A1: ENTITY | B1: PARENT | C1: FIELDTYPE | D1: METADATA | E1: VALUE | F1: BUNDLE | G1: LABEL | H1: RENDERING | I1: STYLE_LABEL | J1: STYLE_VALUE
A2: Person | B2: crisrp.qualification | C2: METADATA | D2: crisrp.qualification | G2: Title | H2: text | I2: font-weight-bold
A3: Person | B3: crisrp.qualification | C3: METADATA | D3: crisrp.qualification.start | G3: Start | H3: date | I3: font-weight-bold
A4: Person | B4: crisrp.qualification | C4: METADATA | D4: crisrp.qualification.end | G4: End | H4: date | I4: font-weight-bold
A5: Person | B5: oairecerif.person.affiliation | C5: METADATA | D5: oairecerif.affiliation.role | G5: Role | H5: text | I5: font-weight-bold
A6: Person | B6: oairecerif.person.affiliation | C6: METADATA | D6: oairecerif.person.affiliation | G6: Organisation | H6: crisref | I6: font-weight-bold
A7: Person | B7: oairecerif.person.affiliation | C7: METADATA | D7: oairecerif.affiliation.startDate | G7: Start | H7: date | I7: font-weight-bold
A8: Person | B8: oairecerif.person.affiliation | C8: METADATA | D8: oairecerif.affiliation.endDate | G8: End | H8: date | I8: font-weight-bold
A9: Person | B9: crisrp.education | C9: METADATA | D9: crisrp.education.role | G9: Role | H9: text | I9: font-weight-bold
A10: Person | B10: crisrp.education | C10: METADATA | D10: crisrp.education | G10: Organisation | H10: crisref | I10: font-weight-bold
A11: Person | B11: crisrp.education | C11: METADATA | D11: crisrp.education.start | G11: Start | H11: date | I11: font-weight-bold
A12: Person | B12: crisrp.education | C12: METADATA | D12: crisrp.education.end | G12: End | H12: date | I12: font-weight-bold
A13: Publication | B13: dc.contributor.author | C13: METADATA | D13: dc.contributor.author | G13: Author | H13: crisref | I13: font-weight-bold
... A19: Publication | B19: dc.contributor.editor | C19: METADATA | D19: oairecerif.editor.affiliation | G19: Affiliation | H19: crisref | I19: font-weight-bold
A20: Publication | B20: dc.type | C20: METADATA | D20: dc.type | H20: text | J20: header-tag header-tag-primary d
A21: Publication | B21: dc.type | C21: METADATA | D21: dc.date.issued | G21: Issue | H21: text | J21: header-tag d
A22: Product | B22: dc.contributor.author | C22: METADATA | D22: dc.contributor.author | G22: Creator | H22: crisref | I22: font-weight-bold
A23: Product | B23: dc.contributor.author | C23: METADATA | D23: oairecerif.author.affiliation | G23: Affiliation | H23: crisref | I23: font-weight-bold
A24: Patent | B24: dc.contributor.author | C24: METADATA | D24: dc.contributor.author | G24: Inventor | H24: crisref | I24: font-weight-bold
A25: Patent | B25: dc.contributor.author | C25: METADATA | D25: oairecerif.author.affiliation | G25: Affiliation | H25: crisref | I25: font-weight-bold
A26: Project | B26: crisfund.investigators | C26: METADATA | D26: crisfund.investigators | G26: Name | H26: crisref | I26: font-weight-bold
A27: Project | B27: crisfund.investigators | C27: METADATA | D27: antarc.affiliation.orcid | G27: Orcid | H27: orcid | I27: font-weight-bold
A28: Project | B28: crisfund.leadorganizations | C28: METADATA | D28: crisfund.leadorganizations | G28: Organization | H28: crisref | I28: font-weight-bold
A29: Project | B29: crisfund.leadorganizations | C29: METADATA | D29: antarc.affiliation.ror | G29: ROR | H29: link | I29: font-weight-bold
A30: Thesis | B30: dc.contributor.author | C30: METADATA | D30: dc.contributor.author | G30: Author | H30: crisref | I30: font-weight-bold
A31: Thesis | B31: dc.contributor.author | C31: METADATA | D31: oairecerif.author.affiliation | G31: Affiliation | H31: crisref | I31: font-weight-bold
A32: Thesis | B32: dc.contributor.author | C32: METADATA | D32: antarc.affiliation.orcid | G32: Orcid | H32: orcid | I32: font-weight-bold
A33: Thesis | B33: dc.contributor.author | C33: METADATA | D33: antarc.affiliation.ror | G33: ROR | H33: link | I33: font-weight-bold

Sheet box2metrics
A1: ENTITY | B1: BOX | C1: METRIC_TYPE
A2: Publication | B2: metrics | C2: scopusCitation, wosCitation
A3: Publication | B3: altmetrics | C3: altmetric, dimensions, plumX
A4: Publication | B4: usagemetrics
A5: Patent | B5: metrics | C5: scopusCitation, wosCitation
A6: Patent | B6: altmetrics | C6: altmetric, dimensions
A7: Patent | B7: usagemetrics | C7: view, download, embedded-view, embedded-download
A8: Product | B8: metrics | C8: scopusCitation, wosCitation
A9: Product | B9: altmetrics | C9: altmetric, dimensions
A10: Product | B10: usagemetrics | C10: view, download, embedded-view, embedded-download
A11: Person | B11: metrics | C11: scopus-author-h-index, scopus-author-coauthor-count, scopus-author-cited-count, scopus-author-citation-count, scopus-author-document-count, wosPersonCitation
A12: Person | B12: usagemetrics
A13: OrgUnit | B13: metrics
A14: Project | B14: metrics
A15: Journal | B15: metrics | C15: view, embedded-view
A16: Event | B16: metrics | C16: view, embedded-view
A17: Equipment | B17: metrics | C17: view, embedded-view
A18: Funding | B18: metrics | C18: view, embedded-view

Sheet tabpolicy
A1: ENTITY | B1: SHORTNAME | C1: METADATA | D1: GROUP | E1: ALTERNATIVE_TO
A2: Person | B2: secure | C2: cris.policy.group

Sheet boxpolicy
A1: ENTITY | B1: SHORTNAME | C1: METADATA | D1: GROUP | E1: ALTERNATIVE_TO
A2: Person | B2: secure | C2: cris.policy.eperson
A3: Funding | B3: financialdata | C3: crisfund.investigators
A4: Funding | B4: financialdata | C4: crisfund.coinvestigators

Sheet utilsdata
A1: BOX-TYPES | B1: METADATA-RENDERING | C1: Security
A2: RELATION | B2: heading | C2: PUBLIC
A3: METADATA | B3: text | C3: ADMINISTRATOR
A4: METRICS | B4: longtext | C4: OWNER ONLY
A5: IIIFVIEWER | B5: link | C5: OWNER & ADMINISTRATOR
B6: link.label | C6: CUSTOM DATA
B7: link.email | C7: CUSTOM DATA & ADMINISTRATOR
B8: date
B9: identifier
B10: identifier.hdl
B11: identifier.doi
B12: identifier.scopus
B13: identifier.researcherid
B14: identifier.mailto
B15: crisref
B16: thumbnail
B17: attachment
B18: advancedattachment
B19: tag
... B21: orcid

Sheet tab_i18n
A1: PREFIX | B1: AUTOGENERATED I18N keys
A2: layout.tab.header. | B2: =IF(OR(ISBLANK(tab!$C2),EXACT(MID(tab!$C2,1,LEN($A$2)),$A$2)),"",""""&$A$2&tab!$A2&"."&tab!$B2&""": """&SUBSTITUTE(tab!$C2,"""","\""")&""",") -> "layout.tab.header.Person.details": "Profile",
B3: =IF(OR(ISBLANK(tab!$C3),EXACT(MID(tab!$C3,1,LEN($A$2)),$A$2)),"",""""&$A$2&tab!$A3&"."&tab!$B3&""": """&SUBSTITUTE(tab!$C3,"""","\""")&""",") -> "layout.tab.header.Person.publications": "Publications",
B4: =IF(OR(ISBLANK(tab!$C4),EXACT(MID(tab!$C4,1,LEN($A$2)),$A$2)),"",""""&$A$2&tab!$A4&"."&tab!$B4&""": """&SUBSTITUTE(tab!$C4,"""","\""")&""",") -> "layout.tab.header.Person.projects": "Projects",
B5: =IF(OR(ISBLANK(tab!$C6),EXACT(MID(tab!$C6,1,LEN($A$2)),$A$2)),"",""""&$A$2&tab!$A6&"."&tab!$B6&""": """&SUBSTITUTE(tab!$C6,"""","\""")&""",") -> "layout.tab.header.Person.otherinfo": "Other",
B6: =IF(OR(ISBLANK(tab!$C7),EXACT(MID(tab!$C7,1,LEN($A$2)),$A$2)),"",""""&$A$2&tab!$A7&"."&tab!$B7&""": """&SUBSTITUTE(tab!$C7,"""","\""")&""",") -> "layout.tab.header.Person.indicators": "Metrics",
B7: =IF(OR(ISBLANK(tab!$C8),EXACT(MID(tab!$C8,1,LEN($A$2)),$A$2)),"",""""&$A$2&tab!$A8&"."&tab!$B8&""": """&SUBSTITUTE(tab!$C8,"""","\""")&""",") -> "layout.tab.header.Person.secure": "Secured Tab",
B8: =IF(OR(ISBLANK(tab!$C9),EXACT(MID(tab!$C9,1,LEN($A$2)),$A$2)),"",""""&$A$2&tab!$A9&"."&tab!$B9&""": """&SUBSTITUTE(tab!$C9,"""","\""")&""",") -> "layout.tab.header.OrgUnit.maininformation": "Information",
B9: =IF(OR(ISBLANK(#REF!),EXACT(MID(#REF!,1,LEN($A$2)),$A$2)),"",""""&$A$2&#REF!&"."&#REF!&""": """&SUBSTITUTE(#REF!,"""","\""")&""",") -> #REF!
B10: =IF(OR(ISBLANK(tab!$C10),EXACT(MID(tab!$C10,1,LEN($A$2)),$A$2)),"",""""&$A$2&tab!$A10&"."&tab!$B10&""": """&SUBSTITUTE(tab!$C10,"""","\""")&""",") -> "layout.tab.header.OrgUnit.organizations": "Organizations",
B11: =IF(OR(ISBLANK(#REF!),EXACT(MID(#REF!,1,LEN($A$2)),$A$2)),"",""""&$A$2&#REF!&"."&#REF!&""": """&SUBSTITUTE(#REF!,"""","\""")&""",") -> #REF!
B12: =IF(OR(ISBLANK(tab!$C11),EXACT(MID(tab!$C11,1,LEN($A$2)),$A$2)),"",""""&$A$2&tab!$A11&"."&tab!$B11&""": """&SUBSTITUTE(tab!$C11,"""","\""")&""",") -> "layout.tab.header.OrgUnit.rppublications": "Researchers publications",
B13: =IF(OR(ISBLANK(tab!$C12),EXACT(MID(tab!$C12,1,LEN($A$2)),$A$2)),"",""""&$A$2&tab!$A12&"."&tab!$B12&""": """&SUBSTITUTE(tab!$C12,"""","\""")&""",") -> "layout.tab.header.OrgUnit.projects": "Projects",
B14: =IF(OR(ISBLANK(tab!$C13),EXACT(MID(tab!$C13,1,LEN($A$2)),$A$2)),"",""""&$A$2&tab!$A13&"."&tab!$B13&""": """&SUBSTITUTE(tab!$C13,"""","\""")&""",") -> "layout.tab.header.OrgUnit.rpprojects": "Researchers projects",
B15: =IF(OR(ISBLANK(tab!$C14),EXACT(MID(tab!$C14,1,LEN($A$2)),$A$2)),"",""""&$A$2&tab!$A14&"."&tab!$B14&""": """&SUBSTITUTE(tab!$C14,"""","\""")&""",") -> "layout.tab.header.OrgUnit.people": "People",
B16: =IF(OR(ISBLANK(tab!$C17),EXACT(MID(tab!$C17,1,LEN($A$2)),$A$2)),"",""""&$A$2&tab!$A17&"."&tab!$B17&""": """&SUBSTITUTE(tab!$C17,"""","\""")&""",") -> "layout.tab.header.Project.details": "Details",
B17: =IF(OR(ISBLANK(tab!$C18),EXACT(MID(tab!$C18,1,LEN($A$2)),$A$2)),"",""""&$A$2&tab!$A18&"."&tab!$B18&""": """&SUBSTITUTE(tab!$C18,"""","\""")&""",") -> "layout.tab.header.Project.outputs::projectoutputs": "Outputs::Publications",
B18: =IF(OR(ISBLANK(tab!$C19),EXACT(MID(tab!$C19,1,LEN($A$2)),$A$2)),"",""""&$A$2&tab!$A19&"."&tab!$B19&""": """&SUBSTITUTE(tab!$C19,"""","\""")&""",") -> "layout.tab.header.Project.outputs::fundings": "Outputs::Fundings",
B19: =IF(OR(ISBLANK(tab!$C20),EXACT(MID(tab!$C20,1,LEN($A$2)),$A$2)),"",""""&$A$2&tab!$A20&"."&tab!$B20&""": """&SUBSTITUTE(tab!$C20,"""","\""")&""",") -> "layout.tab.header.Journal.details": "Details",
B20: =IF(OR(ISBLANK(tab!$C21),EXACT(MID(tab!$C21,1,LEN($A$2)),$A$2)),"",""""&$A$2&tab!$A21&"."&tab!$B21&""": """&SUBSTITUTE(tab!$C21,"""","\""")&""",") -> "layout.tab.header.Event.details": "Details",
B21: =IF(OR(ISBLANK(tab!$C22),EXACT(MID(tab!$C22,1,LEN($A$2)),$A$2)),"",""""&$A$2&tab!$A22&"."&tab!$B22&""": """&SUBSTITUTE(tab!$C22,"""","\""")&""",") -> "layout.tab.header.Equipment.details": "Details",
B22: =IF(OR(ISBLANK(tab!$C23),EXACT(MID(tab!$C23,1,LEN($A$2)),$A$2)),"",""""&$A$2&tab!$A23&"."&tab!$B23&""": """&SUBSTITUTE(tab!$C23,"""","\""")&""",") -> "layout.tab.header.Funding.details": "Details",
B23: =IF(OR(ISBLANK(tab!$C24),EXACT(MID(tab!$C24,1,LEN($A$2)),$A$2)),"",""""&$A$2&tab!$A24&"."&tab!$B24&""": """&SUBSTITUTE(tab!$C24,"""","\""")&""",") -> "layout.tab.header.Publication.details": "Details",
B24: =IF(OR(ISBLANK(tab!$C25),EXACT(MID(tab!$C25,1,LEN($A$2)),$A$2)),"",""""&$A$2&tab!$A25&"."&tab!$B25&""": """&SUBSTITUTE(tab!$C25,"""","\""")&""",") -> "layout.tab.header.Product.details": "Details",
B25: =IF(OR(ISBLANK(tab!$C26),EXACT(MID(tab!$C26,1,LEN($A$2)),$A$2)),"",""""&$A$2&tab!$A26&"."&tab!$B26&""": """&SUBSTITUTE(tab!$C26,"""","\""")&""",") -> "layout.tab.header.Patent.details": "Details",
B26: =IF(OR(ISBLANK(tab!$C27),EXACT(MID(tab!$C27,1,LEN($A$2)),$A$2)),"",""""&$A$2&tab!$A27&"."&tab!$B27&""": """&SUBSTITUTE(tab!$C27,"""","\""")&""",") -> "layout.tab.header.Thesis.details": "Details",
B27: =IF(OR(ISBLANK(tab!$C28),EXACT(MID(tab!$C28,1,LEN($A$2)),$A$2)),"",""""&$A$2&tab!$A28&"."&tab!$B28&""": """&SUBSTITUTE(tab!$C28,"""","\""")&""",")
... B82: =IF(OR(ISBLANK(tab!$C83),EXACT(MID(tab!$C83,1,LEN($A$2)),$A$2)),"",""""&$A$2&tab!$A83&"."&tab!$B83&""": """&SUBSTITUTE(tab!$C83,"""","\""")&""",")

Sheet box_i18n
A1: PREFIX | B1: AUTOGENERATED I18N keys
A2: layout.box.header. | B2: =IF(OR(ISBLANK(box!$E2),EXACT(MID(box!$E2,1,LEN($A$2)),$A$2)),"",""""&$A$2&box!$A2&"."&box!$D2&""": """&SUBSTITUTE(box!$E2,"""","\""")&""",")
B3: =IF(OR(ISBLANK(box!$E3),EXACT(MID(box!$E3,1,LEN($A$2)),$A$2)),"",""""&$A$2&box!$A3&"."&box!$D3&""": """&SUBSTITUTE(box!$E3,"""","\""")&""",") -> "layout.box.header.Person.projects": "Projects",
B4: =IF(OR(ISBLANK(box!$E4),EXACT(MID(box!$E4,1,LEN($A$2)),$A$2)),"",""""&$A$2&box!$A4&"."&box!$D4&""": """&SUBSTITUTE(box!$E4,"""","\""")&""",") -> "layout.box.header.Person.researchoutputs": "Publications",
B5: =IF(OR(ISBLANK(box!$E5),EXACT(MID(box!$E5,1,LEN($A$2)),$A$2)),"",""""&$A$2&box!$A5&"."&box!$D5&""": """&SUBSTITUTE(box!$E5,"""","\""")&""",") -> "layout.box.header.Person.qualifications": "Professional Qualifications",
B6: =IF(OR(ISBLANK(box!$E6),EXACT(MID(box!$E6,1,LEN($A$2)),$A$2)),"",""""&$A$2&box!$A6&"."&box!$D6&""": """&SUBSTITUTE(box!$E6,"""","\""")&""",") -> "layout.box.header.Person.media": "Media Contact Directory",
B7: =IF(OR(ISBLANK(box!$E7),EXACT(MID(box!$E7,1,LEN($A$2)),$A$2)),"",""""&$A$2&box!$A7&"."&box!$D7&""": """&SUBSTITUTE(box!$E7,"""","\""")&""",") -> "layout.box.header.Person.namecard": "Name Card",
B8: =IF(OR(ISBLANK(box!$E8),EXACT(MID(box!$E8,1,LEN($A$2)),$A$2)),"",""""&$A$2&box!$A8&"."&box!$D8&""": """&SUBSTITUTE(box!$E8,"""","\""")&""",") -> "layout.box.header.Person.researcherprofile": "Profile",
B9: =IF(OR(ISBLANK(box!$E9),EXACT(MID(box!$E9,1,LEN($A$2)),$A$2)),"",""""&$A$2&box!$A9&"."&box!$D9&""": """&SUBSTITUTE(box!$E9,"""","\""")&""",") -> "layout.box.header.Person.metrics": "Metrics",
B10: =IF(OR(ISBLANK(box!$E10),EXACT(MID(box!$E10,1,LEN($A$2)),$A$2)),"",""""&$A$2&box!$A10&"."&box!$D10&""": """&SUBSTITUTE(box!$E10,"""","\""")&""",") -> "layout.box.header.Person.usagemetrics": "Usage Metrics",
B11: =IF(OR(ISBLANK(box!$E11),EXACT(MID(box!$E11,1,LEN($A$2)),$A$2)),"",""""&$A$2&box!$A11&"."&box!$D11&""": """&SUBSTITUTE(box!$E11,"""","\""")&""",") -> "layout.box.header.Person.secure": "Secured box",
B12: =IF(OR(ISBLANK(box!$E13),EXACT(MID(box!$E13,1,LEN($A$2)),$A$2)),"",""""&$A$2&box!$A13&"."&box!$D13&""": """&SUBSTITUTE(box!$E13,"""","\""")&""",") -> "layout.box.header.OrgUnit.rpprojects": "OrgUnit's Researchers projects",
B13: =IF(OR(ISBLANK(#REF!),EXACT(MID(#REF!,1,LEN($A$2)),$A$2)),"",""""&$A$2&#REF!&"."&#REF!&""": """&SUBSTITUTE(#REF!,"""","\""")&""",") -> #REF!
B14: =IF(OR(ISBLANK(box!$E14),EXACT(MID(box!$E14,1,LEN($A$2)),$A$2)),"",""""&$A$2&box!$A14&"."&box!$D14&""": """&SUBSTITUTE(box!$E14,"""","\""")&""",") -> "layout.box.header.OrgUnit.rppublications": "OrgUnit's Researchers publications",
B15: =IF(OR(ISBLANK(box!$E15),EXACT(MID(box!$E15,1,LEN($A$2)),$A$2)),"",""""&$A$2&box!$A15&"."&box!$D15&""": """&SUBSTITUTE(box!$E15,"""","\""")&""",") -> "layout.box.header.OrgUnit.people": "OrgUnit's Researchers",
B16: =IF(OR(ISBLANK(box!$E16),EXACT(MID(box!$E16,1,LEN($A$2)),$A$2)),"",""""&$A$2&box!$A16&"."&box!$D16&""": """&SUBSTITUTE(box!$E16,"""","\""")&""",") -> "layout.box.header.OrgUnit.projects": "OrgUnit funded Projects",
B17: =IF(OR(ISBLANK(box!$E18),EXACT(MID(box!$E18,1,LEN($A$2)),$A$2)),"",""""&$A$2&box!$A18&"."&box!$D18&""": """&SUBSTITUTE(box!$E18,"""","\""")&""",")
B18: =IF(OR(ISBLANK(box!$E19),EXACT(MID(box!$E19,1,LEN($A$2)),$A$2)),"",""""&$A$2&box!$A19&"."&box!$D19&""": """&SUBSTITUTE(box!$E19,"""","\""")&""",") -> "layout.box.header.OrgUnit.description": "Description",
B19: =IF(OR(ISBLANK(box!$E20),EXACT(MID(box!$E20,1,LEN($A$2)),$A$2)),"",""""&$A$2&box!$A20&"."&box!$D20&""": """&SUBSTITUTE(box!$E20,"""","\""")&""",") -> "layout.box.header.OrgUnit.organizations": "SubOrgUnits",
B20: =IF(OR(ISBLANK(box!$E21),EXACT(MID(box!$E21,1,LEN($A$2)),$A$2)),"",""""&$A$2&box!$A21&"."&box!$D21&""": """&SUBSTITUTE(box!$E21,"""","\""")&""",") -> "layout.box.header.OrgUnit.details": "Details",
B21: =IF(OR(ISBLANK(box!$E22),EXACT(MID(box!$E22,1,LEN($A$2)),$A$2)),"",""""&$A$2&box!$A22&"."&box!$D22&""": """&SUBSTITUTE(box!$E22,"""","\""")&""",") -> "layout.box.header.OrgUnit.orgcard": "Card",
B22: =IF(OR(ISBLANK(box!$E23),EXACT(MID(box!$E23,1,LEN($A$2)),$A$2)),"",""""&$A$2&box!$A23&"."&box!$D23&""": """&SUBSTITUTE(box!$E23,"""","\""")&""",") -> "layout.box.header.OrgUnit.metrics": "Metrics",
B23: =IF(OR(ISBLANK(box!#REF!),EXACT(MID(box!#REF!,1,LEN($A$2)),$A$2)),"",""""&$A$2&box!#REF!&"."&box!#REF!&""": """&SUBSTITUTE(box!#REF!,"""","\""")&""",") -> #ERROR!
B24: =IF(OR(ISBLANK(box!$E25),EXACT(MID(box!$E25,1,LEN($A$2)),$A$2)),"",""""&$A$2&box!$A25&"."&box!$D25&""": """&SUBSTITUTE(box!$E25,"""","\""")&""",") -> "layout.box.header.Project.researchoutputs": "Publications",
B25: =IF(OR(ISBLANK(box!$E26),EXACT(MID(box!$E26,1,LEN($A$2)),$A$2)),"",""""&$A$2&box!$A26&"."&box!$D26&""": """&SUBSTITUTE(box!$E26,"""","\""")&""",") -> "layout.box.header.Project.fundings": "Fundings",
B26: =IF(OR(ISBLANK(box!$E27),EXACT(MID(box!$E27,1,LEN($A$2)),$A$2)),"",""""&$A$2&box!$A27&"."&box!$D27&""": """&SUBSTITUTE(box!$E27,"""","\""")&""",") -> "layout.box.header.Project.primarydata": "Primary Data",
B27: =IF(OR(ISBLANK(box!$E32),EXACT(MID(box!$E32,1,LEN($A$2)),$A$2)),"",""""&$A$2&box!$A32&"."&box!$D32&""": """&SUBSTITUTE(box!$E32,"""","\""")&""",") -> "layout.box.header.Project.projectcard": "Project Card",
B28: =IF(OR(ISBLANK(box!$E33),EXACT(MID(box!$E33,1,LEN($A$2)),$A$2)),"",""""&$A$2&box!$A33&"."&box!$D33&""": """&SUBSTITUTE(box!$E33,"""","\""")&""",") -> "layout.box.header.Project.metrics": "Metrics",
B29: =IF(OR(ISBLANK(box!$E34),EXACT(MID(box!$E34,1,LEN($A$2)),$A$2)),"",""""&$A$2&box!$A34&"."&box!$D34&""": """&SUBSTITUTE(box!$E34,"""","\""")&""",")
B30: =IF(OR(ISBLANK(box!$E35),EXACT(MID(box!$E35,1,LEN($A$2)),$A$2)),"",""""&$A$2&box!$A35&"."&box!$D35&""": """&SUBSTITUTE(box!$E35,"""","\""")&""",") -> "layout.box.header.Funding.primarydata": "Primary Data",
B31: =IF(OR(ISBLANK(box!$E36),EXACT(MID(box!$E36,1,LEN($A$2)),$A$2)),"",""""&$A$2&box!$A36&"."&box!$D36&""": """&SUBSTITUTE(box!$E36,"""","\""")&""",") -> "layout.box.header.Funding.financialdata": "Financial Data",
B32: =IF(OR(ISBLANK(box!$E37),EXACT(MID(box!$E37,1,LEN($A$2)),$A$2)),"",""""&$A$2&box!$A37&"."&box!$D37&""": """&SUBSTITUTE(box!$E37,"""","\""")&""",") -> "layout.box.header.Funding.metrics": "Metrics",
B33: =IF(OR(ISBLANK(box!$E38),EXACT(MID(box!$E38,1,LEN($A$2)),$A$2)),"",""""&$A$2&box!$A38&"."&box!$D38&""": """&SUBSTITUTE(box!$E38,"""","\""")&""",") -> "layout.box.header.Journal.details": "Journal description",
B34: =IF(OR(ISBLANK(box!$E39),EXACT(MID(box!$E39,1,LEN($A$2)),$A$2)),"",""""&$A$2&box!$A39&"."&box!$D39&""": """&SUBSTITUTE(box!$E39,"""","\""")&""",") -> "layout.box.header.Journal.metrics": "Metrics",
B35: =IF(OR(ISBLANK(box!$E40),EXACT(MID(box!$E40,1,LEN($A$2)),$A$2)),"",""""&$A$2&box!$A40&"."&box!$D40&""": """&SUBSTITUTE(box!$E40,"""","\""")&""",") -> "layout.box.header.Event.details": "Description",
B36: =IF(OR(ISBLANK(box!$E41),EXACT(MID(box!$E41,1,LEN($A$2)),$A$2)),"",""""&$A$2&box!$A41&"."&box!$D41&""": """&SUBSTITUTE(box!$E41,"""","\""")&""",") -> "layout.box.header.Event.metrics": "Metrics",
B37: =IF(OR(ISBLANK(box!$E42),EXACT(MID(box!$E42,1,LEN($A$2)),$A$2)),"",""""&$A$2&box!$A42&"."&box!$D42&""": """&SUBSTITUTE(box!$E42,"""","\""")&""",") -> "layout.box.header.Equipment.details": "Equipment description",
B38: =IF(OR(ISBLANK(box!$E43),EXACT(MID(box!$E43,1,LEN($A$2)),$A$2)),"",""""&$A$2&box!$A43&"."&box!$D43&""": """&SUBSTITUTE(box!$E43,"""","\""")&""",") -> "layout.box.header.Equipment.metrics": "Metrics",
... B44: =IF(OR(ISBLANK(box!$E49),EXACT(MID(box!$E49,1,LEN($A$2)),$A$2)),"",""""&$A$2&box!$A49&"."&box!$D49&""": """&SUBSTITUTE(box!$E49,"""","\""")&""",")
B45: =IF(OR(ISBLANK(box!$E54),EXACT(MID(box!$E54,1,LEN($A$2)),$A$2)),"",""""&$A$2&box!$A54&"."&box!$D54&""": """&SUBSTITUTE(box!$E54,"""","\""")&""",") -> "layout.box.header.Patent.details": "Details",
...

Sheet metadata_i18n
A1: PREFIX | B1: AUTOGENERATED I18N keys
A2: layout.field.label. | B2: =IF(ISBLANK(box2metadata!$I2),"",""""&$A$2&box2metadata!$A2&"."&IF(box2metadata!$E2="BITSTREAM","BITSTREAM"&IF(ISBLANK(box2metadata!$G2),"","["&box2metadata!$G2&"]"),"["&box2metadata!$F2&"]")&""": """&SUBSTITUTE(box2metadata!$I2,"""","\""")&""",") -> "layout.field.label.OrgUnit.[organization.address.addressCountry]": "Country",
B3: =IF(ISBLANK(box2metadata!$I3),"",""""&$A$2&box2metadata!$A3&"."&IF(box2metadata!$E3="BITSTREAM","BITSTREAM"&IF(ISBLANK(box2metadata!$G3),"","["&box2metadata!$G3&"]"),"["&box2metadata!$F3&"]")&""": """&SUBSTITUTE(box2metadata!$I3,"""","\""")&""",") -> "layout.field.label.OrgUnit.[organization.address.addressLocality]": "City",
B4: =IF(ISBLANK(box2metadata!$I4),"",""""&$A$2&box2metadata!$A4&"."&IF(box2metadata!$E4="BITSTREAM","BITSTREAM"&IF(ISBLANK(box2metadata!$G4),"","["&box2metadata!$G4&"]"),"["&box2metadata!$F4&"]")&""": """&SUBSTITUTE(box2metadata!$I4,"""","\""")&""",") -> "layout.field.label.OrgUnit.[dc.description.abstract]": "Description",
B5: =IF(ISBLANK(box2metadata!$I5),"",""""&$A$2&box2metadata!$A5&"."&IF(box2metadata!$E5="BITSTREAM","BITSTREAM"&IF(ISBLANK(box2metadata!$G5),"","["&box2metadata!$G5&"]"),"["&box2metadata!$F5&"]")&""": """&SUBSTITUTE(box2metadata!$I5,"""","\""")&""",")
B6: =IF(ISBLANK(#REF!),"",""""&$A$2&#REF!&"."&IF(#REF!="BITSTREAM","BITSTREAM"&IF(ISBLANK(#REF!),"","["&#REF!&"]"),"["&#REF!&"]")&""": """&SUBSTITUTE(#REF!,"""","\""")&""",") -> #REF!
B7: =IF(ISBLANK(box2metadata!$I6),"",""""&$A$2&box2metadata!$A6&"."&IF(box2metadata!$E6="BITSTREAM","BITSTREAM"&IF(ISBLANK(box2metadata!$G6),"","["&box2metadata!$G6&"]"),"["&box2metadata!$F6&"]")&""": """&SUBSTITUTE(box2metadata!$I6,"""","\""")&""",") -> "layout.field.label.OrgUnit.[oairecerif.acronym]": "Acronym",
B8: =IF(ISBLANK(#REF!),"",""""&$A$2&#REF!&"."&IF(#REF!="BITSTREAM","BITSTREAM"&IF(ISBLANK(#REF!),"","["&#REF!&"]"),"["&#REF!&"]")&""": """&SUBSTITUTE(#REF!,"""","\""")&""",") -> #REF!
B9: =IF(ISBLANK(box2metadata!$I11),"",""""&$A$2&box2metadata!$A11&"."&IF(box2metadata!$E11="BITSTREAM","BITSTREAM"&IF(ISBLANK(box2metadata!$G11),"","["&box2metadata!$G11&"]"),"["&box2metadata!$F11&"]")&""": """&SUBSTITUTE(box2metadata!$I11,"""","\""")&""",") -> "layout.field.label.OrgUnit.[organization.foundingDate]": "Founding Date",
B10: =IF(ISBLANK(box2metadata!$I11),"",""""&$A$2&box2metadata!$A11&"."&IF(box2metadata!$E11="BITSTREAM","BITSTREAM"&IF(ISBLANK(box2metadata!$G11),"","["&box2metadata!$G11&"]"),"["&box2metadata!$F11&"]")&""": """&SUBSTITUTE(box2metadata!$I11,"""","\""")&""",") -> "layout.field.label.OrgUnit.[organization.foundingDate]": "Founding Date",
B11: =IF(ISBLANK(box2metadata!$I12),"",""""&$A$2&box2metadata!$A12&"."&IF(box2metadata!$E12="BITSTREAM","BITSTREAM"&IF(ISBLANK(box2metadata!$G12),"","["&box2metadata!$G12&"]"),"["&box2metadata!$F12&"]")&""": """&SUBSTITUTE(box2metadata!$I12,"""","\""")&""",") -> "layout.field.label.OrgUnit.[organization.identifier.ror]": "ROR Identifier",
B12: =IF(ISBLANK(box2metadata!$I16),"",""""&$A$2&box2metadata!$A16&"."&IF(box2metadata!$E16="BITSTREAM","BITSTREAM"&IF(ISBLANK(box2metadata!$G16),"","["&box2metadata!$G16&"]"),"["&box2metadata!$F16&"]")&""": """&SUBSTITUTE(box2metadata!$I16,"""","\""")&""",")
B13: =IF(ISBLANK(box2metadata!$I17),"",""""&$A$2&box2metadata!$A17&"."&IF(box2metadata!$E17="BITSTREAM","BITSTREAM"&IF(ISBLANK(box2metadata!$G17),"","["&box2metadata!$G17&"]"),"["&box2metadata!$F17&"]")&""": """&SUBSTITUTE(box2metadata!$I17,"""","\""")&""",") -> "layout.field.label.OrgUnit.[dc.title]": "Organisation Name",
B14: =IF(ISBLANK(box2metadata!$I18),"",""""&$A$2&box2metadata!$A18&"."&IF(box2metadata!$E18="BITSTREAM","BITSTREAM"&IF(ISBLANK(box2metadata!$G18),"","["&box2metadata!$G18&"]"),"["&box2metadata!$F18&"]")&""": """&SUBSTITUTE(box2metadata!$I18,"""","\""")&""",") -> "layout.field.label.OrgUnit.[crisou.director]": "Director",
B15: =IF(ISBLANK(box2metadata!$I19),"",""""&$A$2&box2metadata!$A19&"."&IF(box2metadata!$E19="BITSTREAM","BITSTREAM"&IF(ISBLANK(box2metadata!$G19),"","["&box2metadata!$G19&"]"),"["&box2metadata!$F19&"]")&""": """&SUBSTITUTE(box2metadata!$I19,"""","\""")&""",") -> "layout.field.label.OrgUnit.[organization.parentOrganization]": "Parent Organisation",
B16: =IF(ISBLANK(box2metadata!$I20),"",""""&$A$2&box2metadata!$A20&"."&IF(box2metadata!$E20="BITSTREAM","BITSTREAM"&IF(ISBLANK(box2metadata!$G20),"","["&box2metadata!$G20&"]"),"["&box2metadata!$F20&"]")&""": """&SUBSTITUTE(box2metadata!$I20,"""","\""")&""",") -> "layout.field.label.OrgUnit.[organization.foundingDate]": "Founding Date",
B17: =IF(ISBLANK(box2metadata!$I21),"",""""&$A$2&box2metadata!$A21&"."&IF(box2metadata!$E21="BITSTREAM","BITSTREAM"&IF(ISBLANK(box2metadata!$G21),"","["&box2metadata!$G21&"]"),"["&box2metadata!$F21&"]")&""": """&SUBSTITUTE(box2metadata!$I21,"""","\""")&""",") -> "layout.field.label.OrgUnit.[organization.address.addressLocality]": "City",
B18: =IF(ISBLANK(box2metadata!$I22),"",""""&$A$2&box2metadata!$A22&"."&IF(box2metadata!$E22="BITSTREAM","BITSTREAM"&IF(ISBLANK(box2metadata!$G22),"","["&box2metadata!$G22&"]"),"["&box2metadata!$F22&"]")&""": """&SUBSTITUTE(box2metadata!$I22,"""","\""")&""",") -> "layout.field.label.OrgUnit.[organization.address.addressCountry]": "Country",
B19: =IF(ISBLANK(box2metadata!#REF!),"",""""&$A$2&box2metadata!#REF!&"."&IF(box2metadata!#REF!="BITSTREAM","BITSTREAM"&IF(ISBLANK(box2metadata!#REF!),"","["&box2metadata!#REF!&"]"),"["&box2metadata!#REF!&"]")&""": """&SUBSTITUTE(box2metadata!#REF!,"""","\""")&""",") -> #ERROR!
B20: =IF(ISBLANK(box2metadata!#REF!),"",""""&$A$2&box2metadata!#REF!&"."&IF(box2metadata!#REF!="BITSTREAM","BITSTREAM"&IF(ISBLANK(box2metadata!#REF!),"","["&box2metadata!#REF!&"]"),"["&box2metadata!#REF!&"]")&""": """&SUBSTITUTE(box2metadata!#REF!,"""","\""")&""",") -> #ERROR!
B21: =IF(ISBLANK(box2metadata!#REF!),"",""""&$A$2&box2metadata!#REF!&"."&IF(box2metadata!#REF!="BITSTREAM","BITSTREAM"&IF(ISBLANK(box2metadata!#REF!),"","["&box2metadata!#REF!&"]"),"["&box2metadata!#REF!&"]")&""": """&SUBSTITUTE(box2metadata!#REF!,"""","\""")&""",") -> #ERROR!
B22: =IF(ISBLANK(box2metadata!$I24),"",""""&$A$2&box2metadata!$A24&"."&IF(box2metadata!$E24="BITSTREAM","BITSTREAM"&IF(ISBLANK(box2metadata!$G24),"","["&box2metadata!$G24&"]"),"["&box2metadata!$F24&"]")&""": """&SUBSTITUTE(box2metadata!$I24,"""","\""")&""",") -> "layout.field.label.Project.[oairecerif.acronym]": "INACH Code",
B23: =IF(ISBLANK(box2metadata!$I23),"",""""&$A$2&box2metadata!$A23&"."&IF(box2metadata!$E23="BITSTREAM","BITSTREAM"&IF(ISBLANK(box2metadata!$G23),"","["&box2metadata!$G23&"]"),"["&box2metadata!$F23&"]")&""": """&SUBSTITUTE(box2metadata!$I23,"""","\""")&""",")
B24: =IF(ISBLANK(box2metadata!$I24),"",""""&$A$2&box2metadata!$A24&"."&IF(box2metadata!$E24="BITSTREAM","BITSTREAM"&IF(ISBLANK(box2metadata!$G24),"","["&box2metadata!$G24&"]"),"["&box2metadata!$F24&"]")&""": """&SUBSTITUTE(box2metadata!$I24,"""","\""")&""",") -> "layout.field.label.Project.[oairecerif.acronym]": "INACH Code",
B25: =IF(ISBLANK(box2metadata!$I38),"",""""&$A$2&box2metadata!$A38&"."&IF(box2metadata!$E38="BITSTREAM","BITSTREAM"&IF(ISBLANK(box2metadata!$G38),"","["&box2metadata!$G38&"]"),"["&box2metadata!$F38&"]")&""": """&SUBSTITUTE(box2metadata!$I38,"""","\""")&""",")
B26: =IF(ISBLANK(box2metadata!$I39),"",""""&$A$2&box2metadata!$A39&"."&IF(box2metadata!$E39="BITSTREAM","BITSTREAM"&IF(ISBLANK(box2metadata!$G39),"","["&box2metadata!$G39&"]"),"["&box2metadata!$F39&"]")&""": """&SUBSTITUTE(box2metadata!$I39,"""","\""")&""",") -> "layout.field.label.Project.[dc.title]": "Project Title",
B27: =IF(ISBLANK(box2metadata!$I40),"",""""&$A$2&box2metadata!$A40&"."&IF(box2metadata!$E40="BITSTREAM","BITSTREAM"&IF(ISBLANK(box2metadata!$G40),"","["&box2metadata!$G40&"]"),"["&box2metadata!$F40&"]")&""": """&SUBSTITUTE(box2metadata!$I40,"""","\""")&""",") -> "layout.field.label.Project.[oairecerif.internalid]": "Internal ID",
B28: =IF(ISBLANK(box2metadata!$I41),"",""""&$A$2&box2metadata!$A41&"."&IF(box2metadata!$E41="BITSTREAM","BITSTREAM"&IF(ISBLANK(box2metadata!$G41),"","["&box2metadata!$G41&"]"),"["&box2metadata!$F41&"]")&""": """&SUBSTITUTE(box2metadata!$I41,"""","\""")&""",") -> "layout.field.label.Project.[oairecerif.project.status]": "Status",
B29: =IF(ISBLANK(box2metadata!$I42),"",""""&$A$2&box2metadata!$A42&"."&IF(box2metadata!$E42="BITSTREAM","BITSTREAM"&IF(ISBLANK(box2metadata!$G42),"","["&box2metadata!$G42&"]"),"["&box2metadata!$F42&"]")&""": """&SUBSTITUTE(box2metadata!$I42,"""","\""")&""",") -> "layout.field.label.Project.[oairecerif.project.startDate]": "Start Date",
B30: =IF(ISBLANK(box2metadata!$I43),"",""""&$A$2&box2metadata!$A43&"."&IF(box2metadata!$E43="BITSTREAM","BITSTREAM"&IF(ISBLANK(box2metadata!$G43),"","["&box2metadata!$G43&"]"),"["&box2metadata!$F43&"]")&""": """&SUBSTITUTE(box2metadata!$I43,"""","\""")&""",") -> "layout.field.label.Project.[oairecerif.project.endDate]": "End Date",
B31: =IF(ISBLANK(box2metadata!$I44),"",""""&$A$2&box2metadata!$A44&"."&IF(box2metadata!$E44="BITSTREAM","BITSTREAM"&IF(ISBLANK(box2metadata!$G44),"","["&box2metadata!$G44&"]"),"["&box2metadata!$F44&"]")&""": """&SUBSTITUTE(box2metadata!$I44,"""","\""")&""",")
B32: =IF(ISBLANK(box2metadata!$I45),"",""""&$A$2&box2metadata!$A45&"."&IF(box2metadata!$E45="BITSTREAM","BITSTREAM"&IF(ISBLANK(box2metadata!$G45),"","["&box2metadata!$G45&"]"),"["&box2metadata!$F45&"]")&""": """&SUBSTITUTE(box2metadata!$I45,"""","\""")&""",") -> "layout.field.label.Funding.[dc.relation.project]": "Project",
B33: =IF(ISBLANK(box2metadata!$I46),"",""""&$A$2&box2metadata!$A46&"."&IF(box2metadata!$E46="BITSTREAM","BITSTREAM"&IF(ISBLANK(box2metadata!$G46),"","["&box2metadata!$G46&"]"),"["&box2metadata!$F46&"]")&""": """&SUBSTITUTE(box2metadata!$I46,"""","\""")&""",") -> "layout.field.label.Funding.[dc.type]": "Type",
B34: =IF(ISBLANK(box2metadata!$I47),"",""""&$A$2&box2metadata!$A47&"."&IF(box2metadata!$E47="BITSTREAM","BITSTREAM"&IF(ISBLANK(box2metadata!$G47),"","["&box2metadata!$G47&"]"),"["&box2metadata!$F47&"]")&""": """&SUBSTITUTE(box2metadata!$I47,"""","\""")&""",") -> "layout.field.label.Funding.[oairecerif.funder]": "Funder",
B35: =IF(ISBLANK(box2metadata!$I48),"",""""&$A$2&box2metadata!$A48&"."&IF(box2metadata!$E48="BITSTREAM","BITSTREAM"&IF(ISBLANK(box2metadata!$G48),"","["&box2metadata!$G48&"]"),"["&box2metadata!$F48&"]")&""": """&SUBSTITUTE(box2metadata!$I48,"""","\""")&""",") -> "layout.field.label.Funding.[oairecerif.fundingParent]": "Funding Program",
B36: =IF(ISBLANK(box2metadata!$I38),"",""""&$A$2&box2metadata!$A38&"."&IF(box2metadata!$E38="BITSTREAM","BITSTREAM"&IF(ISBLANK(box2metadata!$G38),"","["&box2metadata!$G38&"]"),"["&box2metadata!$F38&"]")&""": """&SUBSTITUTE(box2metadata!$I38,"""","\""")&""",")
B37: =IF(ISBLANK(box2metadata!$I39),"",""""&$A$2&box2metadata!$A39&"."&IF(box2metadata!$E39="BITSTREAM","BITSTREAM"&IF(ISBLANK(box2metadata!$G39),"","["&box2metadata!$G39&"]"),"["&box2metadata!$F39&"]")&""": """&SUBSTITUTE(box2metadata!$I39,"""","\""")&""",") -> "layout.field.label.Project.[dc.title]": "Project Title",
B38: =IF(ISBLANK(box2metadata!$I40),"",""""&$A$2&box2metadata!$A40&"."&IF(box2metadata!$E40="BITSTREAM","BITSTREAM"&IF(ISBLANK(box2metadata!$G40),"","["&box2metadata!$G40&"]"),"["&box2metadata!$F40&"]")&""": """&SUBSTITUTE(box2metadata!$I40,"""","\""")&""",") -> "layout.field.label.Project.[oairecerif.internalid]": "Internal ID",
B39: =IF(ISBLANK(box2metadata!$I41),"",""""&$A$2&box2metadata!$A41&"."&IF(box2metadata!$E41="BITSTREAM","BITSTREAM"&IF(ISBLANK(box2metadata!$G41),"","["&box2metadata!$G41&"]"),"["&box2metadata!$F41&"]")&""": """&SUBSTITUTE(box2metadata!$I41,"""","\""")&""",") -> "layout.field.label.Project.[oairecerif.project.status]": "Status",
B40: =IF(ISBLANK(box2metadata!$I42),"",""""&$A$2&box2metadata!$A42&"."&IF(box2metadata!$E42="BITSTREAM","BITSTREAM"&IF(ISBLANK(box2metadata!$G42),"","["&box2metadata!$G42&"]"),"["&box2metadata!$F42&"]")&""": """&SUBSTITUTE(box2metadata!$I42,"""","\""")&""",") -> "layout.field.label.Project.[oairecerif.project.startDate]": "Start Date",
...

Sheet metadatagroup_i18n
A1: PREFIX | B1: AUTOGENERATED I18N keys
A2: layout.field.label. | B2: =IF(ISBLANK(metadatagroups!$B2),"",""""&$A$2&metadatagroups!$A2&"."&"NESTED"&"["&metadatagroups!$D2&"]"&""": """&SUBSTITUTE(metadatagroups!$G2,"""","\""")&""",") -> "layout.field.label.Person.NESTED[crisrp.qualification]": "Title",
B3: =IF(ISBLANK(metadatagroups!$B3),"",""""&$A$2&metadatagroups!$A3&"."&"NESTED"&"["&metadatagroups!$D3&"]"&""": """&SUBSTITUTE(metadatagroups!$G3,"""","\""")&""",") -> "layout.field.label.Person.NESTED[crisrp.qualification.start]": "Start",
B4: =IF(ISBLANK(metadatagroups!$B4),"",""""&$A$2&metadatagroups!$A4&"."&"NESTED"&"["&metadatagroups!$D4&"]"&""": """&SUBSTITUTE(metadatagroups!$G4,"""","\""")&""",") -> "layout.field.label.Person.NESTED[crisrp.qualification.end]": "End",
B5: =IF(ISBLANK(metadatagroups!$B5),"",""""&$A$2&metadatagroups!$A5&"."&"NESTED"&"["&metadatagroups!$D5&"]"&""": """&SUBSTITUTE(metadatagroups!$G5,"""","\""")&""",") -> "layout.field.label.Person.NESTED[oairecerif.affiliation.role]": "Role",
B6: =IF(ISBLANK(metadatagroups!$B6),"",""""&$A$2&metadatagroups!$A6&"."&"NESTED"&"["&metadatagroups!$D6&"]"&""": """&SUBSTITUTE(metadatagroups!$G6,"""","\""")&""",") -> "layout.field.label.Person.NESTED[oairecerif.person.affiliation]": "Organisation",
B7: =IF(ISBLANK(metadatagroups!$B7),"",""""&$A$2&metadatagroups!$A7&"."&"NESTED"&"["&metadatagroups!$D7&"]"&""": """&SUBSTITUTE(metadatagroups!$G7,"""","\""")&""",") -> "layout.field.label.Person.NESTED[oairecerif.affiliation.startDate]": "Start",
B8: =IF(ISBLANK(metadatagroups!$B8),"",""""&$A$2&metadatagroups!$A8&"."&"NESTED"&"["&metadatagroups!$D8&"]"&""": """&SUBSTITUTE(metadatagroups!$G8,"""","\""")&""",") -> "layout.field.label.Person.NESTED[oairecerif.affiliation.endDate]": "End",
B9: =IF(ISBLANK(metadatagroups!$B9),"",""""&$A$2&metadatagroups!$A9&"."&"NESTED"&"["&metadatagroups!$D9&"]"&""": """&SUBSTITUTE(metadatagroups!$G9,"""","\""")&""",") -> "layout.field.label.Person.NESTED[crisrp.education.role]": "Role",
B10: =IF(ISBLANK(metadatagroups!$B10),"",""""&$A$2&metadatagroups!$A10&"."&"NESTED"&"["&metadatagroups!$D10&"]"&""": """&SUBSTITUTE(metadatagroups!$G10,"""","\""")&""",") -> "layout.field.label.Person.NESTED[crisrp.education]": "Organisation",
B11: =IF(ISBLANK(metadatagroups!$B11),"",""""&$A$2&metadatagroups!$A11&"."&"NESTED"&"["&metadatagroups!$D11&"]"&""": """&SUBSTITUTE(metadatagroups!$G11,"""","\""")&""",") -> "layout.field.label.Person.NESTED[crisrp.education.start]": "Start",
B12: =IF(ISBLANK(metadatagroups!$B12),"",""""&$A$2&metadatagroups!$A12&"."&"NESTED"&"["&metadatagroups!$D12&"]"&""": """&SUBSTITUTE(metadatagroups!$G12,"""","\""")&""",") -> "layout.field.label.Person.NESTED[crisrp.education.end]": "End",
B13: =IF(ISBLANK(metadatagroups!$B13),"",""""&$A$2&metadatagroups!$A13&"."&"NESTED"&"["&metadatagroups!$D13&"]"&""": """&SUBSTITUTE(metadatagroups!$G13,"""","\""")&""",") -> "layout.field.label.Publication.NESTED[dc.contributor.author]": "Author",
B14: =IF(ISBLANK(metadatagroups!$B14),"",""""&$A$2&metadatagroups!$A14&"."&"NESTED"&"["&metadatagroups!$D14&"]"&""": """&SUBSTITUTE(metadatagroups!$G14,"""","\""")&""",") -> "layout.field.label.Publication.NESTED[oairecerif.author.affiliation]": "Affiliation",
B15: =IF(ISBLANK(metadatagroups!$B18),"",""""&$A$2&metadatagroups!$A18&"."&"NESTED"&"["&metadatagroups!$D18&"]"&""": """&SUBSTITUTE(metadatagroups!$G18,"""","\""")&""",") -> "layout.field.label.Publication.NESTED[dc.contributor.editor]": "Editor",
B16: =IF(ISBLANK(metadatagroups!$B19),"",""""&$A$2&metadatagroups!$A19&"."&"NESTED"&"["&metadatagroups!$D19&"]"&""": """&SUBSTITUTE(metadatagroups!$G19,"""","\""")&""",") -> "layout.field.label.Publication.NESTED[oairecerif.editor.affiliation]": "Affiliation",
B17: =IF(ISBLANK(metadatagroups!$B22),"",""""&$A$2&metadatagroups!$A22&"."&"NESTED"&"["&metadatagroups!$D22&"]"&""": """&SUBSTITUTE(metadatagroups!$G22,"""","\""")&""",") -> "layout.field.label.Product.NESTED[dc.contributor.author]": "Creator",
B18: =IF(ISBLANK(metadatagroups!$B23),"",""""&$A$2&metadatagroups!$A23&"."&"NESTED"&"["&metadatagroups!$D23&"]"&""": """&SUBSTITUTE(metadatagroups!$G23,"""","\""")&""",") -> "layout.field.label.Product.NESTED[oairecerif.author.affiliation]": "Affiliation",
B19: =IF(ISBLANK(metadatagroups!$B24),"",""""&$A$2&metadatagroups!$A24&"."&"NESTED"&"["&metadatagroups!$D24&"]"&""": """&SUBSTITUTE(metadatagroups!$G24,"""","\""")&""",") -> "layout.field.label.Patent.NESTED[dc.contributor.author]": "Inventor",
B20: =IF(ISBLANK(metadatagroups!$B25),"",""""&$A$2&metadatagroups!$A25&"."&"NESTED"&"["&metadatagroups!$D25&"]"&""": """&SUBSTITUTE(metadatagroups!$G25,"""","\""")&""",") -> "layout.field.label.Patent.NESTED[oairecerif.author.affiliation]": "Affiliation",
B21: =IF(ISBLANK(metadatagroups!$B26),"",""""&$A$2&metadatagroups!$A26&"."&"NESTED"&"["&metadatagroups!$D26&"]"&""": """&SUBSTITUTE(metadatagroups!$G26,"""","\""")&""",") -> "layout.field.label.Project.NESTED[crisfund.investigators]": "Name",
B22: =IF(ISBLANK(metadatagroups!$B27),"",""""&$A$2&metadatagroups!$A27&"."&"NESTED"&"["&metadatagroups!$D27&"]"&""": """&SUBSTITUTE(metadatagroups!$G27,"""","\""")&""",") -> "layout.field.label.Project.NESTED[antarc.affiliation.orcid]": "Orcid",
B23: =IF(ISBLANK(metadatagroups!$B28),"",""""&$A$2&metadatagroups!$A28&"."&"NESTED"&"["&metadatagroups!$D28&"]"&""": """&SUBSTITUTE(metadatagroups!$G28,"""","\""")&""",") -> "layout.field.label.Project.NESTED[crisfund.leadorganizations]": "Organization",
B24: =IF(ISBLANK(metadatagroups!$B29),"",""""&$A$2&metadatagroups!$A29&"."&"NESTED"&"["&metadatagroups!$D29&"]"&""": """&SUBSTITUTE(metadatagroups!$G29,"""","\""")&""",") -> "layout.field.label.Project.NESTED[antarc.affiliation.ror]": "ROR",
B25: =IF(ISBLANK(metadatagroups!$B30),"",""""&$A$2&metadatagroups!$A30&"."&"NESTED"&"["&metadatagroups!$D30&"]"&""": """&SUBSTITUTE(metadatagroups!$G30,"""","\""")&""",") -> "layout.field.label.Thesis.NESTED[dc.contributor.author]": "Author",
B26: =IF(ISBLANK(metadatagroups!$B31),"",""""&$A$2&metadatagroups!$A31&"."&"NESTED"&"["&metadatagroups!$D31&"]"&""": """&SUBSTITUTE(metadatagroups!$G31,"""","\""")&""",") -> "layout.field.label.Thesis.NESTED[oairecerif.author.affiliation]": "Affiliation",
B27: =IF(ISBLANK(metadatagroups!$B32),"",""""&$A$2&metadatagroups!$A32&"."&"NESTED"&"["&metadatagroups!$D32&"]"&""": """&SUBSTITUTE(metadatagroups!$G32,"""","\""")&""",") -> "layout.field.label.Thesis.NESTED[antarc.affiliation.orcid]": "Orcid",
B28: =IF(ISBLANK(metadatagroups!$B33),"",""""&$A$2&metadatagroups!$A33&"."&"NESTED"&"["&metadatagroups!$D33&"]"&""": """&SUBSTITUTE(metadatagroups!$G33,"""","\""")&""",") -> "layout.field.label.Thesis.NESTED[antarc.affiliation.ror]": "ROR",
B29: =IF(ISBLANK(#REF!),"",""""&$A$2&#REF!&"."&"NESTED"&"["&#REF!&"]"&""": """&SUBSTITUTE(#REF!,"""","\""")&""",") -> #REF!
B30: =IF(ISBLANK(#REF!),"",""""&$A$2&#REF!&"."&"NESTED"&"["&#REF!&"]"&""": """&SUBSTITUTE(#REF!,"""","\""")&""",") -> #REF!
B31: =IF(ISBLANK(#REF!),"",""""&$A$2&#REF!&"."&"NESTED"&"["&#REF!&"]"&""": """&SUBSTITUTE(#REF!,"""","\""")&""",") -> #REF!
B32: =IF(ISBLANK(metadatagroups!$B34),"",""""&$A$2&metadatagroups!$A34&"."&"NESTED"&"["&metadatagroups!$D34&"]"&""": """&SUBSTITUTE(metadatagroups!$G34,"""","\""")&""",")
B33: =IF(ISBLANK(metadatagroups!$B35),"",""""&$A$2&metadatagroups!$A35&"."&"NESTED"&"["&metadatagroups!$D35&"]"&""": """&SUBSTITUTE(metadatagroups!$G35,"""","\""")&""",")
B34: =IF(ISBLANK(metadatagroups!$B36),"",""""&$A$2&metadatagroups!$A36&"."&"NESTED"&"["&metadatagroups!$D36&"]"&""": """&SUBSTITUTE(metadatagroups!$G36,"""","\""")&""",")
B35: =IF(ISBLANK(metadatagroups!$B37),"",""""&$A$2&metadatagroups!$A37&"."&"NESTED"&"["&metadatagroups!$D37&"]"&""": """&SUBSTITUTE(metadatagroups!$G37,"""","\""")&""",")
B36: =IF(ISBLANK(metadatagroups!$B38),"",""""&$A$2&metadatagroups!$A38&"."&"NESTED"&"["&metadatagroups!$D38&"]"&""": """&SUBSTITUTE(metadatagroups!$G38,"""","\""")&""",")
B37: =IF(ISBLANK(metadatagroups!$B39),"",""""&$A$2&metadatagroups!$A39&"."&"NESTED"&"["&metadatagroups!$D39&"]"&""": """&SUBSTITUTE(metadatagroups!$G39,"""","\""")&""",")
B38: =IF(ISBLANK(metadatagroups!$B40),"",""""&$A$2&metadatagroups!$A40&"."&"NESTED"&"["&metadatagroups!$D40&"]"&""": """&SUBSTITUTE(metadatagroups!$G40,"""","\""")&""",")
B39: =IF(ISBLANK(metadatagroups!$B41),"",""""&$A$2&metadatagroups!$A41&"."&"NESTED"&"["&metadatagroups!$D41&"]"&""": """&SUBSTITUTE(metadatagroups!$G41,"""","\""")&""",")
B40: =IF(ISBLANK(metadatagroups!$B42),"",""""&$A$2&metadatagroups!$A42&"."&"NESTED"&"["&metadatagroups!$D42&"]"&""": """&SUBSTITUTE(metadatagroups!$G42,"""","\""")&""",")
...
